<?xml version="1.0" ?>
<robot name="Fusion2URDF" xmlns:xacro="http://www.ros.org/wiki/xacro">

<xacro:include filename="$(find Fusion2URDF_description)/urdf/materials.xacro" />
<xacro:include filename="$(find Fusion2URDF_description)/urdf/Fusion2URDF.trans" />
<xacro:include filename="$(find Fusion2URDF_description)/urdf/Fusion2URDF.gazebo" />
<link name="base_link">
  <inertial>
    <origin xyz="-0.15239089248396806 -0.10243188731128752 -0.014756658436731226" rpy="0 0 0"/>
    <mass value="12.10296352271439"/>
    <inertia ixx="0.088382" iyy="0.156005" izz="0.175336" ixy="0.001695" iyz="0.001069" ixz="-0.001793"/>
  </inertial>
  <visual>
    <origin xyz="0 0 0" rpy="0 0 0"/>
    <geometry>
      <mesh filename="package://Fusion2URDF_description/meshes/base_link.stl" scale="0.001 0.001 0.001"/>
    </geometry>
    <material name="silver"/>
  </visual>
  <collision>
    <origin xyz="0 0 0" rpy="0 0 0"/>
    <geometry>
      <mesh filename="package://Fusion2URDF_description/meshes/base_link.stl" scale="0.001 0.001 0.001"/>
    </geometry>
  </collision>
</link>

<link name="motor_mount_1">
  <inertial>
    <origin xyz="-0.01981276318460265 -0.04982898469216032 0.06040931610563551" rpy="0 0 0"/>
    <mass value="1.1722540905080954"/>
    <inertia ixx="0.002714" iyy="0.003585" izz="0.001392" ixy="-0.000166" iyz="0.00045" ixz="0.000773"/>
  </inertial>
  <visual>
    <origin xyz="0.15066 0.151463 -0.019629" rpy="0 0 0"/>
    <geometry>
      <mesh filename="package://Fusion2URDF_description/meshes/motor_mount_1.stl" scale="0.001 0.001 0.001"/>
    </geometry>
    <material name="silver"/>
  </visual>
  <collision>
    <origin xyz="0.15066 0.151463 -0.019629" rpy="0 0 0"/>
    <geometry>
      <mesh filename="package://Fusion2URDF_description/meshes/motor_mount_1.stl" scale="0.001 0.001 0.001"/>
    </geometry>
  </collision>
</link>

<link name="front_case_1">
  <inertial>
    <origin xyz="0.004747964856895576 -0.0037055665782579073 -0.000474430017634489" rpy="0 0 0"/>
    <mass value="0.8962608123125344"/>
    <inertia ixx="0.001757" iyy="0.002692" izz="0.001716" ixy="-7.9e-05" iyz="2e-06" ixz="6e-06"/>
  </inertial>
  <visual>
    <origin xyz="0.185535 0.237733 -0.112179" rpy="0 0 0"/>
    <geometry>
      <mesh filename="package://Fusion2URDF_description/meshes/front_case_1.stl" scale="0.001 0.001 0.001"/>
    </geometry>
    <material name="silver"/>
  </visual>
  <collision>
    <origin xyz="0.185535 0.237733 -0.112179" rpy="0 0 0"/>
    <geometry>
      <mesh filename="package://Fusion2URDF_description/meshes/front_case_1.stl" scale="0.001 0.001 0.001"/>
    </geometry>
  </collision>
</link>

<link name="rear_case_241023_1">
  <inertial>
    <origin xyz="-0.0018600683258184203 -0.00819787091579846 -0.0010903891552709044" rpy="0 0 0"/>
    <mass value="0.21930558501864583"/>
    <inertia ixx="0.000346" iyy="0.000681" izz="0.000363" ixy="1e-06" iyz="3e-06" ixz="1.2e-05"/>
  </inertial>
  <visual>
    <origin xyz="0.185535 0.213463 -0.112179" rpy="0 0 0"/>
    <geometry>
      <mesh filename="package://Fusion2URDF_description/meshes/rear_case_241023_1.stl" scale="0.001 0.001 0.001"/>
    </geometry>
    <material name="silver"/>
  </visual>
  <collision>
    <origin xyz="0.185535 0.213463 -0.112179" rpy="0 0 0"/>
    <geometry>
      <mesh filename="package://Fusion2URDF_description/meshes/rear_case_241023_1.stl" scale="0.001 0.001 0.001"/>
    </geometry>
  </collision>
</link>

<link name="planetary_gearset_rotor_bottom_1">
  <inertial>
    <origin xyz="-3.562159705261525e-07 0.004693595537344553 -4.2982606343611174e-07" rpy="0 0 0"/>
    <mass value="0.1070548461839941"/>
    <inertia ixx="2.1e-05" iyy="4e-05" izz="2.1e-05" ixy="0.0" iyz="0.0" ixz="0.0"/>
  </inertial>
  <visual>
    <origin xyz="0.185535 0.271333 -0.112179" rpy="0 0 0"/>
    <geometry>
      <mesh filename="package://Fusion2URDF_description/meshes/planetary_gearset_rotor_bottom_1.stl" scale="0.001 0.001 0.001"/>
    </geometry>
    <material name="silver"/>
  </visual>
  <collision>
    <origin xyz="0.185535 0.271333 -0.112179" rpy="0 0 0"/>
    <geometry>
      <mesh filename="package://Fusion2URDF_description/meshes/planetary_gearset_rotor_bottom_1.stl" scale="0.001 0.001 0.001"/>
    </geometry>
  </collision>
</link>

<link name="bearing_1">
  <inertial>
    <origin xyz="-3.5668971021252105e-07 -0.003500416695875974 -4.298609793673691e-07" rpy="0 0 0"/>
    <mass value="0.008940871381981142"/>
    <inertia ixx="4e-06" iyy="8e-06" izz="4e-06" ixy="0.0" iyz="0.0" ixz="0.0"/>
  </inertial>
  <visual>
    <origin xyz="0.185535 0.263333 -0.112179" rpy="0 0 0"/>
    <geometry>
      <mesh filename="package://Fusion2URDF_description/meshes/bearing_1.stl" scale="0.001 0.001 0.001"/>
    </geometry>
    <material name="silver"/>
  </visual>
  <collision>
    <origin xyz="0.185535 0.263333 -0.112179" rpy="0 0 0"/>
    <geometry>
      <mesh filename="package://Fusion2URDF_description/meshes/bearing_1.stl" scale="0.001 0.001 0.001"/>
    </geometry>
  </collision>
</link>

<link name="test_bar_1">
  <inertial>
    <origin xyz="-0.2703333566338234 0.17870476849989464 -0.16287648681238087" rpy="0 0 0"/>
    <mass value="0.33133706662052054"/>
    <inertia ixx="0.001228" iyy="0.001264" izz="4.1e-05" ixy="0.0" iyz="-2e-05" ixz="0.0"/>
  </inertial>
  <visual>
    <origin xyz="-0.084798 0.455869 -0.224357" rpy="0 0 0"/>
    <geometry>
      <mesh filename="package://Fusion2URDF_description/meshes/test_bar_1.stl" scale="0.001 0.001 0.001"/>
    </geometry>
    <material name="silver"/>
  </visual>
  <collision>
    <origin xyz="-0.084798 0.455869 -0.224357" rpy="0 0 0"/>
    <geometry>
      <mesh filename="package://Fusion2URDF_description/meshes/test_bar_1.stl" scale="0.001 0.001 0.001"/>
    </geometry>
  </collision>
</link>

<link name="mass_plate_1">
  <inertial>
    <origin xyz="-3.5654069860391324e-07 -0.015000416695875984 -4.2986097931185796e-07" rpy="0 0 0"/>
    <mass value="13.129065500806407"/>
    <inertia ixx="0.019268" iyy="0.036596" izz="0.019268" ixy="0.0" iyz="0.0" ixz="-0.0"/>
  </inertial>
  <visual>
    <origin xyz="0.185535 0.280833 0.077821" rpy="0 0 0"/>
    <geometry>
      <mesh filename="package://Fusion2URDF_description/meshes/mass_plate_1.stl" scale="0.001 0.001 0.001"/>
    </geometry>
    <material name="silver"/>
  </visual>
  <collision>
    <origin xyz="0.185535 0.280833 0.077821" rpy="0 0 0"/>
    <geometry>
      <mesh filename="package://Fusion2URDF_description/meshes/mass_plate_1.stl" scale="0.001 0.001 0.001"/>
    </geometry>
  </collision>
</link>

<joint name="悪端 7" type="fixed">
  <origin xyz="-0.15066 -0.151463 0.019629" rpy="0 0 0"/>
  <parent link="base_link"/>
  <child link="motor_mount_1"/>
</joint>

<joint name="悪端 9" type="fixed">
  <origin xyz="0.0 -0.02427 0.0" rpy="0 0 0"/>
  <parent link="rear_case_241023_1"/>
  <child link="front_case_1"/>
</joint>

<joint name="悪端 10" type="fixed">
  <origin xyz="-0.034875 -0.062 0.09255" rpy="0 0 0"/>
  <parent link="motor_mount_1"/>
  <child link="rear_case_241023_1"/>
</joint>

<joint name="悪端 11" type="fixed">
  <origin xyz="0.0 -0.0336 0.0" rpy="0 0 0"/>
  <parent link="front_case_1"/>
  <child link="planetary_gearset_rotor_bottom_1"/>
</joint>

<joint name="悪端 12" type="fixed">
  <origin xyz="0.0 0.008 0.0" rpy="0 0 0"/>
  <parent link="planetary_gearset_rotor_bottom_1"/>
  <child link="bearing_1"/>
</joint>

<joint name="噺穿 13" type="continuous">
  <origin xyz="0.270333 -0.192536 0.112178" rpy="0 0 0"/>
  <parent link="bearing_1"/>
  <child link="test_bar_1"/>
  <axis xyz="0.0 1.0 0.0"/>
</joint>

<joint name="悪端 14" type="fixed">
  <origin xyz="-0.270333 0.175036 -0.302178" rpy="0 0 0"/>
  <parent link="test_bar_1"/>
  <child link="mass_plate_1"/>
</joint>

</robot>
