<?xml version="1.0" ?>
<robot name="simple_pendulum_editted" xmlns:xacro="http://www.ros.org/wiki/xacro">

  <xacro:include filename="$(find simple_pendulum_description)/urdf/materials.xacro" />
  <!-- <xacro:include filename="$(find simple_pendulum_editted_description)/urdf/simple_pendulum_editted.trans" /> -->
  <!-- <xacro:include filename="$(find simple_pendulum_editted_description)/urdf/simple_pendulum_editted.gazebo" /> -->

  <link name="base_link">
    <inertial>
      <origin xyz="0.0004996117854216743 4.5784050473674376e-07 0.3615103798417151" rpy="0 0 0"/>
      <mass value="4.145737620648409"/>
      <inertia ixx="0.237248" iyy="0.177967" izz="0.060655" ixy="0.0" iyz="0.0" ixz="-0.000725"/>
    </inertial>
    <visual>
      <origin xyz="0 0 0" rpy="0 0 0"/>
      <geometry>
        <mesh filename="file://$(find simple_pendulum_description)/meshes/editted/base_link.stl" scale="0.001 0.001 0.001"/>
      </geometry>
      <material name="silver"/>
    </visual>
    <collision>
      <origin xyz="0 0 0" rpy="0 0 0"/>
      <geometry>
        <mesh filename="file://$(find simple_pendulum_description)/meshes/editted/base_link.stl" scale="0.001 0.001 0.001"/>
      </geometry>
    </collision>
  </link>

  <link name="tmotor_ak80_64_1">
    <inertial>
      <origin xyz="0.02295418293149583 2.120148207704231e-05 -8.588628726624581e-05" rpy="0 0 0"/>
      <mass value="1.9847572941595912"/>
      <inertia ixx="0.002295" iyy="0.001558" izz="0.001552" ixy="1e-06" iyz="1e-06" ixz="-5e-06"/>
    </inertial>
    <visual>
      <origin xyz="-0.017 -0.0 -0.69779" rpy="0 0 0"/>
      <geometry>
        <mesh filename="file://$(find simple_pendulum_description)/meshes/editted/tmotor_ak80_64_1.stl" scale="0.001 0.001 0.001"/>
      </geometry>
      <material name="silver"/>
    </visual>
    <collision>
      <origin xyz="-0.017 -0.0 -0.69779" rpy="0 0 0"/>
      <geometry>
        <mesh filename="file://$(find simple_pendulum_description)/meshes/editted/tmotor_ak80_64_1.stl" scale="0.001 0.001 0.001"/>
      </geometry>
    </collision>
  </link>

  <link name="pendulum_1">
    <inertial>
      <origin xyz="0.029518189781869777 0.00025241669217958003 -0.18227709919098878" rpy="0 0 0"/>
      <mass value="0.6431423721098941"/>
      <inertia ixx="0.009345" iyy="0.009741" izz="0.000732" ixy="-2e-06" iyz="1.2e-05" ixz="0.001265"/>
    </inertial>
    <visual>
      <origin xyz="-0.0677 -0.0 -0.69779" rpy="0 0 0"/>
      <geometry>
        <mesh filename="file://$(find simple_pendulum_description)/meshes/editted/pendulum_1.stl" scale="0.001 0.001 0.001"/>
      </geometry>
      <material name="silver"/>
    </visual>
    <collision>
      <origin xyz="-0.0677 -0.0 -0.69779" rpy="0 0 0"/>
      <geometry>
        <mesh filename="file://$(find simple_pendulum_description)/meshes/editted/pendulum_1.stl" scale="0.001 0.001 0.001"/>
      </geometry>
    </collision>
  </link>

  <link name="circular_mass_1">
    <inertial>
      <origin xyz="0.014999999999921049 2.0743501213775495e-07 1.0247154907938594e-07" rpy="0 0 0"/>
      <mass value="10.00116203793268"/>
      <inertia ixx="0.099543" iyy="0.050521" izz="0.050521" ixy="0.0" iyz="0.0" ixz="0.0"/>
    </inertial>
    <visual>
      <origin xyz="-0.0857 -0.000415 -0.39779" rpy="0 0 0"/>
      <geometry>
        <mesh filename="file://$(find simple_pendulum_description)/meshes/editted/circular_mass_1.stl" scale="0.001 0.001 0.001"/>
      </geometry>
      <material name="silver"/>
    </visual>
    <collision>
      <origin xyz="-0.0857 -0.000415 -0.39779" rpy="0 0 0"/>
      <geometry>
        <mesh filename="file://$(find simple_pendulum_description)/meshes/editted/circular_mass_1.stl" scale="0.001 0.001 0.001"/>
      </geometry>
    </collision>
  </link>

  <joint name="fixed_joint_motor" type="fixed">
    <origin xyz="0.017 0.0 0.69779" rpy="0 0 0"/>
    <parent link="base_link"/>
    <child link="tmotor_ak80_64_1"/>
  </joint>

  <joint name="continuous_joint" type="continuous">
    <origin xyz="0.0507 0.0 0.0" rpy="0 0 0"/>
    <parent link="tmotor_ak80_64_1"/>
    <child link="pendulum_1"/>
    <axis xyz="1.0 0.0 -0.0"/>
  </joint>

  <joint name="fixed_joint_mass" type="fixed">
    <origin xyz="0.018 0.000415 -0.3" rpy="0 0 0"/>
    <parent link="pendulum_1"/>
    <child link="circular_mass_1"/>
  </joint>

</robot>
