<?xml version="1.0" ?>
<!-- =================================================================================== -->
<!-- |    This document was autogenerated by xacro from simple_pendulum.xacro          | -->
<!-- |    EDITING THIS FILE BY HAND IS NOT RECOMMENDED                                 | -->
<!-- =================================================================================== -->
<robot name="simple_pendulum">
  <material name="silver">
    <color rgba="0.700 0.700 0.700 1.000"/>
  </material>
  <!-- <xacro:include filename="$(find simple_pendulum_editted_description)/urdf/simple_pendulum_editted.trans" /> -->
  <!-- <xacro:include filename="$(find simple_pendulum_editted_description)/urdf/simple_pendulum_editted.gazebo" /> -->
  <link name="base_link">
    <inertial>
      <origin rpy="0 0 0" xyz="0.0004996117854216743 4.5784050473674376e-07 0.3615103798417151"/>
      <mass value="4.145737620648409"/>
      <inertia ixx="0.237248" ixy="0.0" ixz="-0.000725" iyy="0.177967" iyz="0.0" izz="0.060655"/>
    </inertial>
    <visual>
      <origin rpy="0 0 0" xyz="0 0 0"/>
      <geometry>
        <mesh filename="package://simple_pendulum_description/meshes/editted/base_link.stl" scale="0.001 0.001 0.001"/>
      </geometry>
      <material name="silver"/>
    </visual>
    <collision>
      <origin rpy="0 0 0" xyz="0 0 0"/>
      <geometry>
        <mesh filename="package://simple_pendulum_description/meshes/editted/base_link.stl" scale="0.001 0.001 0.001"/>
      </geometry>
    </collision>
  </link>
  <link name="tmotor_ak80_64_1">
    <inertial>
      <origin rpy="0 0 0" xyz="0.02295418293149583 2.120148207704231e-05 -8.588628726624581e-05"/>
      <mass value="1.9847572941595912"/>
      <inertia ixx="0.002295" ixy="1e-06" ixz="-5e-06" iyy="0.001558" iyz="1e-06" izz="0.001552"/>
    </inertial>
    <visual>
      <origin rpy="0 0 0" xyz="-0.017 -0.0 -0.69779"/>
      <geometry>
        <mesh filename="package://simple_pendulum_description/meshes/editted/tmotor_ak80_64_1.stl" scale="0.001 0.001 0.001"/>
      </geometry>
      <material name="silver"/>
    </visual>
    <collision>
      <origin rpy="0 0 0" xyz="-0.017 -0.0 -0.69779"/>
      <geometry>
        <mesh filename="package://simple_pendulum_description/meshes/editted/tmotor_ak80_64_1.stl" scale="0.001 0.001 0.001"/>
      </geometry>
    </collision>
  </link>
  <link name="pendulum_1">
    <inertial>
      <origin rpy="0 0 0" xyz="0.029518189781869777 0.00025241669217958003 -0.18227709919098878"/>
      <mass value="0.6431423721098941"/>
      <inertia ixx="0.009345" ixy="-2e-06" ixz="0.001265" iyy="0.009741" iyz="1.2e-05" izz="0.000732"/>
    </inertial>
    <visual>
      <origin rpy="0 0 0" xyz="-0.0677 -0.0 -0.69779"/>
      <geometry>
        <mesh filename="package://simple_pendulum_description/meshes/editted/pendulum_1.stl" scale="0.001 0.001 0.001"/>
      </geometry>
      <material name="silver"/>
    </visual>
    <collision>
      <origin rpy="0 0 0" xyz="-0.0677 -0.0 -0.69779"/>
      <geometry>
        <mesh filename="package://simple_pendulum_description/meshes/editted/pendulum_1.stl" scale="0.001 0.001 0.001"/>
      </geometry>
    </collision>
  </link>
  <link name="circular_mass_1">
    <inertial>
      <origin rpy="0 0 0" xyz="0.014999999999921049 2.0743501213775495e-07 1.0247154907938594e-07"/>
      <mass value="10.00116203793268"/>
      <inertia ixx="0.099543" ixy="0.0" ixz="0.0" iyy="0.050521" iyz="0.0" izz="0.050521"/>
    </inertial>
    <visual>
      <origin rpy="0 0 0" xyz="-0.0857 -0.000415 -0.39779"/>
      <geometry>
        <mesh filename="package://simple_pendulum_description/meshes/editted/circular_mass_1.stl" scale="0.001 0.001 0.001"/>
      </geometry>
      <material name="silver"/>
    </visual>
    <collision>
      <origin rpy="0 0 0" xyz="-0.0857 -0.000415 -0.39779"/>
      <geometry>
        <mesh filename="package://simple_pendulum_description/meshes/editted/circular_mass_1.stl" scale="0.001 0.001 0.001"/>
      </geometry>
    </collision>
  </link>
  <joint name="fixed_joint_motor" type="fixed">
    <origin rpy="0 0 0" xyz="0.017 0.0 0.69779"/>
    <parent link="base_link"/>
    <child link="tmotor_ak80_64_1"/>
  </joint>
  <joint name="continuous_joint" type="continuous">
    <origin rpy="0 0 0" xyz="0.0507 0.0 0.0"/>
    <parent link="tmotor_ak80_64_1"/>
    <child link="pendulum_1"/>
    <axis xyz="1.0 0.0 -0.0"/>
  </joint>
  <joint name="fixed_joint_mass" type="fixed">
    <origin rpy="0 0 0" xyz="0.018 0.000415 -0.3"/>
    <parent link="pendulum_1"/>
    <child link="circular_mass_1"/>
  </joint>
</robot>
