<?xml version="1.0" ?>
<!-- =================================================================================== -->
<!-- |    This document was autogenerated by xacro from simple_pendulum_editted.xacro  | -->
<!-- |    EDITING THIS FILE BY HAND IS NOT RECOMMENDED                                 | -->
<!-- =================================================================================== -->
<robot name="simple_pendulum_editted">
  <material name="silver">
    <color rgba="0.700 0.700 0.700 1.000"/>
  </material>
  <!-- <xacro:include filename="$(find simple_pendulum_description)/urdf/simple_pendulum_editted.trans" /> -->
  <!-- <xacro:include filename="$(find simple_pendulum_description)/urdf/simple_pendulum_editted.gazebo" /> -->
  <link name="base_link">
    <inertial>
      <origin rpy="0 0 0" xyz="0.0004996117854216743 4.5784050473674376e-07 0.3615103798417151"/>
      <mass value="0.7536951069708316"/>
      <inertia ixx="0.043132" ixy="0.0" ixz="-0.000132" iyy="0.032354" iyz="0.0" izz="0.011027"/>
    </inertial>
    <visual>
      <origin rpy="0 0 0" xyz="0 0 0"/>
      <geometry>
        <mesh filename="package://simple_pendulum_description/meshes/editted/base_link.stl" scale="0.001 0.001 0.001"/>
      </geometry>
      <material name="silver"/>
    </visual>
    <collision>
      <origin rpy="0 0 0" xyz="0 0 0"/>
      <geometry>
        <mesh filename="package://simple_pendulum_description/meshes/editted/base_link.stl" scale="0.001 0.001 0.001"/>
      </geometry>
    </collision>
  </link>
  <link name="tmotor_ak80_64_1">
    <inertial>
      <origin rpy="0 0 0" xyz="0.022954182931495835 2.120148207704231e-05 -8.588628726624581e-05"/>
      <mass value="0.36082887968650246"/>
      <inertia ixx="0.000417" ixy="0.0" ixz="-1e-06" iyy="0.000283" iyz="0.0" izz="0.000282"/>
    </inertial>
    <visual>
      <origin rpy="0 0 0" xyz="-0.017 -0.0 -0.69779"/>
      <geometry>
        <mesh filename="package://simple_pendulum_description/meshes/editted/tmotor_ak80_64_1.stl" scale="0.001 0.001 0.001"/>
      </geometry>
      <material name="silver"/>
    </visual>
    <collision>
      <origin rpy="0 0 0" xyz="-0.017 -0.0 -0.69779"/>
      <geometry>
        <mesh filename="package://simple_pendulum_description/meshes/editted/tmotor_ak80_64_1.stl" scale="0.001 0.001 0.001"/>
      </geometry>
    </collision>
  </link>
  <link name="pendulum_1">
    <inertial>
      <origin rpy="0 0 0" xyz="0.029518189781869722 0.0002524166921795777 -0.182277099190989"/>
      <mass value="0.6431423721098946"/>
      <inertia ixx="0.009345" ixy="-2e-06" ixz="0.001265" iyy="0.009741" iyz="1.2e-05" izz="0.000732"/>
    </inertial>
    <visual>
      <origin rpy="0 0 0" xyz="-0.0677 -0.0 -0.69779"/>
      <geometry>
        <mesh filename="package://simple_pendulum_description/meshes/editted/pendulum_1.stl" scale="0.001 0.001 0.001"/>
      </geometry>
      <material name="silver"/>
    </visual>
    <collision>
      <origin rpy="0 0 0" xyz="-0.0677 -0.0 -0.69779"/>
      <geometry>
        <mesh filename="package://simple_pendulum_description/meshes/editted/pendulum_1.stl" scale="0.001 0.001 0.001"/>
      </geometry>
    </collision>
  </link>
  <joint name="fixed_joint" type="fixed">
    <origin rpy="0 0 0" xyz="0.017 0.0 0.69779"/>
    <parent link="base_link"/>
    <child link="tmotor_ak80_64_1"/>
  </joint>
  <joint name="continuous_joint" type="continuous">
    <origin rpy="0 0 0" xyz="0.0507 0.0 0.0"/>
    <parent link="tmotor_ak80_64_1"/>
    <child link="pendulum_1"/>
    <axis xyz="1.0 0.0 -0.0"/>
  </joint>
</robot>
